<?xml version="1.0" ?>
<!-- =================================================================================== -->
<!-- |    This document was autogenerated by xacro from bicopter.xacro                 | -->
<!-- |    EDITING THIS FILE BY HAND IS NOT RECOMMENDED                                 | -->
<!-- =================================================================================== -->
<robot name="bicopter" xmlns:xacro="http://wiki.ros.org/xacro">
  <!-- END - Include -->
  <material name="blue">
    <color rgba="0 0 0.8 1"/>
  </material>
  <material name="white">
    <color rgba="1 1 1 1"/>
  </material>
  <material name="props">
    <color rgba="0 0 0 0.5"/>
  </material>
  <link name="base_link">
    <inertial>
      <mass value="0.5"/>
      <origin rpy="0 0 0" xyz="0 0 0.05"/>
      <inertia ixx="0.3" ixy="0" ixz="0" iyy="0.3" iyz="0" izz="0.3"/>
    </inertial>
    <collision>
      <origin rpy="0 0 0" xyz="0 0 0.05"/>
      <geometry>
        <box size="0.2 0.06 0.10"/>
      </geometry>
    </collision>
    <visual>
      <origin rpy="0 0 0" xyz="0 0 0.05"/>
      <geometry>
        <box size="0.2 0.06 0.10"/>
      </geometry>
      <material name="white"/>
    </visual>
  </link>
  <link name="tail">
    <inertial>
      <mass value="0.02085"/>
      <origin rpy="0 1.5708 0" xyz="0 0 0.0"/>
      <inertia ixx="1e-05" ixy="0" ixz="0" iyy="1e-05" iyz="0" izz="1e-05"/>
    </inertial>
    <collision>
      <origin rpy="0 1.5708 0" xyz="0 0 0.0"/>
      <geometry>
        <cylinder length="0.3" radius="0.01"/>
      </geometry>
    </collision>
    <visual>
      <origin rpy="0 1.5708 0" xyz="0 0 0.0"/>
      <geometry>
        <cylinder length="0.3" radius="0.01"/>
      </geometry>
      <material name="white"/>
    </visual>
  </link>
  <link name="prop_right">
    <inertial>
      <mass value="0.01"/>
      <origin rpy="0 0 0" xyz="0 0 0.0"/>
      <inertia ixx="1e-05" ixy="0" ixz="0" iyy="1e-05" iyz="0" izz="1e-05"/>
    </inertial>
    <collision>
      <origin rpy="0 0 0" xyz="0 0 0.0"/>
      <geometry>
        <cylinder length="0.005" radius="0.12"/>
      </geometry>
    </collision>
    <visual>
      <origin rpy="0 0 0" xyz="0 0 0.0"/>
      <geometry>
        <cylinder length="0.005" radius="0.12"/>
      </geometry>
      <material name="props"/>
    </visual>
  </link>
  <link name="prop_left">
    <inertial>
      <mass value="0.01"/>
      <origin rpy="0 0 0" xyz="0 0 0.0"/>
      <inertia ixx="1e-05" ixy="0" ixz="0" iyy="1e-05" iyz="0" izz="1e-05"/>
    </inertial>
    <collision>
      <origin rpy="0 0 0" xyz="0 0 0.0"/>
      <geometry>
        <cylinder length="0.005" radius="0.12"/>
      </geometry>
    </collision>
    <visual>
      <origin rpy="0 0 0" xyz="0 0 0.0"/>
      <geometry>
        <cylinder length="0.005" radius="0.12"/>
      </geometry>
      <material name="props"/>
    </visual>
  </link>
  <link name="arm_left">
    <inertial>
      <mass value="0.05"/>
      <origin rpy="0 -0.1 -1.5707" xyz="-0.010 -0.1 0.02"/>
      <inertia ixx="1e-05" ixy="0" ixz="0" iyy="1e-05" iyz="0" izz="1e-05"/>
    </inertial>
    <collision>
      <origin rpy="0 -0.1 -1.5707" xyz="-0.010 -0.1 0.02"/>
      <geometry>
        <box size="0.2 0.02 0.02"/>
      </geometry>
    </collision>
    <visual>
      <origin rpy="0 -0.1 -1.5707" xyz="-0.010 -0.1 0.02"/>
      <geometry>
        <box size="0.2 0.02 0.02"/>
      </geometry>
      <material name="blue"/>
    </visual>
  </link>
  <link name="arm_right">
    <inertial>
      <mass value="0.05"/>
      <origin rpy="0 -0.1 1.5707" xyz="-0.010 0.1 0.02"/>
      <inertia ixx="1e-05" ixy="0" ixz="0" iyy="1e-05" iyz="0" izz="1e-05"/>
    </inertial>
    <collision>
      <origin rpy="0 -0.1 1.5707" xyz="-0.010 0.1 0.02"/>
      <geometry>
        <box size="0.2 0.02 0.02"/>
      </geometry>
    </collision>
    <visual>
      <origin rpy="0 -0.1 1.5707" xyz="-0.010 0.1 0.02"/>
      <geometry>
        <box size="0.2 0.02 0.02"/>
      </geometry>
      <material name="blue"/>
    </visual>
  </link>
  <link name="motor_right">
    <inertial>
      <mass value="0.035"/>
      <origin rpy="0 0 0" xyz="0 0 0.0"/>
      <inertia ixx="1e-05" ixy="0" ixz="0" iyy="1e-05" iyz="0" izz="1e-05"/>
    </inertial>
    <collision>
      <origin rpy="0 0 0" xyz="0 0 0.0"/>
      <geometry>
        <cylinder length="0.05" radius="0.02"/>
      </geometry>
    </collision>
    <visual>
      <origin rpy="0 0 0" xyz="0 0 0.0"/>
      <geometry>
        <cylinder length="0.05" radius="0.02"/>
      </geometry>
      <material name="white"/>
    </visual>
  </link>
  <link name="motor_left">
    <inertial>
      <mass value="0.035"/>
      <origin rpy="0 0 0" xyz="0 0 0.0"/>
      <inertia ixx="1e-05" ixy="0" ixz="0" iyy="1e-05" iyz="0" izz="1e-05"/>
    </inertial>
    <collision>
      <origin rpy="0 0 0" xyz="0 0 0.0"/>
      <geometry>
        <cylinder length="0.05" radius="0.02"/>
      </geometry>
    </collision>
    <visual>
      <origin rpy="0 0 0" xyz="0 0 0.0"/>
      <geometry>
        <cylinder length="0.05" radius="0.02"/>
      </geometry>
      <material name="white"/>
    </visual>
  </link>
  <joint name="link_base_link_tail" type="fixed">
    <parent link="base_link"/>
    <child link="tail"/>
    <origin xyz="-0.25 0.0 0.05"/>
  </joint>
  <joint name="link_base_link_arm_right" type="fixed">
    <parent link="base_link"/>
    <child link="arm_right"/>
    <origin xyz="0 0.0 0.05"/>
  </joint>
  <joint name="link_base_link_arm_left" type="fixed">
    <parent link="base_link"/>
    <child link="arm_left"/>
    <origin xyz="0 0.0 0.05"/>
  </joint>
  <joint name="arm_right__motor_right" type="revolute">
    <axis xyz="0 1 0"/>
    <limit effort="1000" lower="-0.5" upper="0.5" velocity="0.5"/>
    <origin rpy="0 0 0" xyz="-0.010 0.2 0.04"/>
    <parent link="arm_right"/>
    <child link="motor_right"/>
    <dynamics damping="10.0" friction="10.0"/>
  </joint>
  <joint name="arm_left__motor_left" type="revolute">
    <axis xyz="0 1 0"/>
    <limit effort="1000" lower="-0.5" upper="0.5" velocity="0.5"/>
    <origin rpy="0 0 0" xyz="-0.010 -0.2 0.04"/>
    <parent link="arm_left"/>
    <child link="motor_left"/>
    <dynamics damping="10.0" friction="10.0"/>
  </joint>
  <joint name="motor_left__prop_left" type="continuous">
    <axis xyz="0 0 -1"/>
    <origin rpy="0 0 0" xyz="0.00 -0.0 0.02"/>
    <parent link="motor_left"/>
    <child link="prop_left"/>
  </joint>
  <joint name="motor_right__prop_right" type="continuous">
    <axis xyz="0 0 1"/>
    <origin rpy="0 0 0" xyz="0.00  0.0 0.02"/>
    <parent link="motor_right"/>
    <child link="prop_right"/>
  </joint>
  <gazebo reference="base_link">
    <material>Gazebo/Gray</material>
  </gazebo>
  <gazebo reference="prop_right">
    <material>Gazebo/Blue</material>
  </gazebo>
  <gazebo reference="prop_left">
    <material>Gazebo/Blue</material>
  </gazebo>
  <!-- This plugin will publish the joint_states for the selected joints 
          (which robot_state_publisher can then use to broadcast the approprate tf). -->
  <gazebo>
    <plugin filename="libgazebo_ros_joint_state_publisher.so" name="gazebo_ros_joint_state_publisher">
      <update_rate>20</update_rate>
      <joint_name>arm_left__motor_left</joint_name>
      <joint_name>arm_right__motor_right</joint_name>
      <joint_name>motor_left__prop_left</joint_name>
      <joint_name>motor_right__prop_right</joint_name>
    </plugin>
  </gazebo>
  <!-- This plugin will read a JointTrajectory message from the /set_joint_trajectory topic 
          and move the machine accordingly. It's a bit clunky but it works. -->
  <!-- You'll probably want to add damping to the joints to stop them it flopping around. 
          e.g. <dynamics damping="10.0" friction="10.0"/> -->
  <!-- Here's an example message to publish to test it:

          ros2 topic pub -1 /set_joint_trajectory trajectory_msgs/msg/JointTrajectory  '{header: {frame_id: world}, joint_names: [arm_left__motor_left], points: [  {positions: {0.3}} ]}'
          ros2 topic pub -1 /set_joint_trajectory trajectory_msgs/msg/JointTrajectory  '{header: {frame_id: world}, joint_names: [arm_right__motor_right], points: [  {positions: {0.3}} ]}'
          -->
  <gazebo>
    <plugin filename="libgazebo_ros_joint_pose_trajectory.so" name="gazebo_ros_joint_pose_trajectory">
      <update_rate>20</update_rate>
    </plugin>
  </gazebo>
  <!-- Ros Gazebo force Plugin -->
  <!-- http://wiki.ros.org/pr2_gazebo_plugins/Tutorials/Attaching%20a%20GazeboRosForce%20pugin%20to%20Objects%20in%20Simulation
  https://docs.ros.org/en/ros2_packages/rolling/api/gazebo_plugins/generated/classgazebo__plugins_1_1GazeboRosForce.html

  ros2 topic pub -1 /force/prop_left  geometry_msgs/Wrench  '{force:  {x: 0.0, y: 0.0, z: 1000.00}, torque: {x: 0.0,y: 0.0,z: 0.0}}'
  ros2 topic pub -1 /cmd/prop_left  std_msgs/Float32 '{data: 3.0}'
  ros2 topic pub -1 /cmd/prop_right  std_msgs/Float32 '{data: 3.0}'
    -->
  <gazebo>
    <plugin filename="libgazebo_ros_force.so" name="gazebo_ros_force">
      <ros>
        <!-- Add a namespace -->
        <namespace>/force</namespace>
        <!-- Remap the default topic -->
        <remapping>gazebo_ros_force:=prop_right</remapping>
      </ros>
      <force_frame>link</force_frame>
      <link_name>motor_right</link_name>
      <!-- <bodyName>${motor_right}</bodyName> -->
    </plugin>
  </gazebo>
  <gazebo>
    <plugin filename="libgazebo_ros_force.so" name="gazebo_ros_force">
      <ros>
        <!-- Add a namespace -->
        <namespace>/force</namespace>
        <!-- Remap the default topic -->
        <remapping>gazebo_ros_force:=prop_left</remapping>
      </ros>
      <force_frame>link</force_frame>
      <link_name>motor_left</link_name>
      <!-- <bodyName>${motor_left}</bodyName> -->
    </plugin>
  </gazebo>
  <gazebo reference="base_link">
    <gravity>true</gravity>
    <sensor name="imu_sensor" type="imu">
      <always_on>true</always_on>
      <update_rate>100</update_rate>
      <visualize>true</visualize>
      <topic>imu</topic>
      <plugin filename="libgazebo_ros_imu_sensor.so" name="imu_plugin">
        <topicName>imu</topicName>
        <bodyName>base_link</bodyName>
        <updateRateHZ>10.0</updateRateHZ>
        <gaussianNoise>0.0</gaussianNoise>
        <xyzOffset>0 0 0</xyzOffset>
        <rpyOffset>0 0 0</rpyOffset>
        <frameName>base_link</frameName>
        <initialOrientationAsReference>false</initialOrientationAsReference>
      </plugin>
      <pose>0 0 0 0 0 0</pose>
    </sensor>
  </gazebo>
</robot>

